2020-02-08 18:07:35,404 ERROR: Exception on /reset_password_request [POST] [in c:\users\admin\desktop\flask-demo-app\venv\lib\site-packages\flask\app.py:1890]
Traceback (most recent call last):
  File "c:\users\admin\desktop\flask-demo-app\venv\lib\site-packages\flask\app.py", line 2446, in wsgi_app
    response = self.full_dispatch_request()
  File "c:\users\admin\desktop\flask-demo-app\venv\lib\site-packages\flask\app.py", line 1951, in full_dispatch_request
    rv = self.handle_user_exception(e)
  File "c:\users\admin\desktop\flask-demo-app\venv\lib\site-packages\flask\app.py", line 1820, in handle_user_exception
    reraise(exc_type, exc_value, tb)
  File "c:\users\admin\desktop\flask-demo-app\venv\lib\site-packages\flask\_compat.py", line 39, in reraise
    raise value
  File "c:\users\admin\desktop\flask-demo-app\venv\lib\site-packages\flask\app.py", line 1949, in full_dispatch_request
    rv = self.dispatch_request()
  File "c:\users\admin\desktop\flask-demo-app\venv\lib\site-packages\flask\app.py", line 1935, in dispatch_request
    return self.view_functions[rule.endpoint](**req.view_args)
  File "C:\Users\Admin\Desktop\flask-demo-app\app\routes.py", line 154, in reset_password_request
    send_password_reset_email(user)
  File "C:\Users\Admin\Desktop\flask-demo-app\app\email.py", line 13, in send_password_reset_email
    send_email(
  File "C:\Users\Admin\Desktop\flask-demo-app\app\email.py", line 9, in send_email
    mail.send(msg)
  File "c:\users\admin\desktop\flask-demo-app\venv\lib\site-packages\flask_mail.py", line 491, in send
    with self.connect() as connection:
  File "c:\users\admin\desktop\flask-demo-app\venv\lib\site-packages\flask_mail.py", line 144, in __enter__
    self.host = self.configure_host()
  File "c:\users\admin\desktop\flask-demo-app\venv\lib\site-packages\flask_mail.py", line 158, in configure_host
    host = smtplib.SMTP(self.mail.server, self.mail.port)
  File "c:\users\admin\appdata\local\programs\python\python38\Lib\smtplib.py", line 253, in __init__
    (code, msg) = self.connect(host, port)
  File "c:\users\admin\appdata\local\programs\python\python38\Lib\smtplib.py", line 339, in connect
    self.sock = self._get_socket(host, port, self.timeout)
  File "c:\users\admin\appdata\local\programs\python\python38\Lib\smtplib.py", line 308, in _get_socket
    return socket.create_connection((host, port), timeout,
  File "c:\users\admin\appdata\local\programs\python\python38\Lib\socket.py", line 807, in create_connection
    raise err
  File "c:\users\admin\appdata\local\programs\python\python38\Lib\socket.py", line 796, in create_connection
    sock.connect(sa)
ConnectionRefusedError: [WinError 10061] No connection could be made because the target machine actively refused it
2020-02-08 18:10:11,329 INFO: Microblog startup [in C:\Users\Admin\Desktop\flask-demo-app\app\__init__.py:55]
2020-02-08 18:10:23,735 ERROR: Exception on /reset_password_request [POST] [in c:\users\admin\desktop\flask-demo-app\venv\lib\site-packages\flask\app.py:1890]
Traceback (most recent call last):
  File "c:\users\admin\desktop\flask-demo-app\venv\lib\site-packages\flask\app.py", line 2446, in wsgi_app
    response = self.full_dispatch_request()
  File "c:\users\admin\desktop\flask-demo-app\venv\lib\site-packages\flask\app.py", line 1951, in full_dispatch_request
    rv = self.handle_user_exception(e)
  File "c:\users\admin\desktop\flask-demo-app\venv\lib\site-packages\flask\app.py", line 1820, in handle_user_exception
    reraise(exc_type, exc_value, tb)
  File "c:\users\admin\desktop\flask-demo-app\venv\lib\site-packages\flask\_compat.py", line 39, in reraise
    raise value
  File "c:\users\admin\desktop\flask-demo-app\venv\lib\site-packages\flask\app.py", line 1949, in full_dispatch_request
    rv = self.dispatch_request()
  File "c:\users\admin\desktop\flask-demo-app\venv\lib\site-packages\flask\app.py", line 1935, in dispatch_request
    return self.view_functions[rule.endpoint](**req.view_args)
  File "C:\Users\Admin\Desktop\flask-demo-app\app\routes.py", line 154, in reset_password_request
    send_password_reset_email(user)
  File "C:\Users\Admin\Desktop\flask-demo-app\app\email.py", line 13, in send_password_reset_email
    send_email(
  File "C:\Users\Admin\Desktop\flask-demo-app\app\email.py", line 9, in send_email
    mail.send(msg)
  File "c:\users\admin\desktop\flask-demo-app\venv\lib\site-packages\flask_mail.py", line 491, in send
    with self.connect() as connection:
  File "c:\users\admin\desktop\flask-demo-app\venv\lib\site-packages\flask_mail.py", line 144, in __enter__
    self.host = self.configure_host()
  File "c:\users\admin\desktop\flask-demo-app\venv\lib\site-packages\flask_mail.py", line 158, in configure_host
    host = smtplib.SMTP(self.mail.server, self.mail.port)
  File "c:\users\admin\appdata\local\programs\python\python38\Lib\smtplib.py", line 253, in __init__
    (code, msg) = self.connect(host, port)
  File "c:\users\admin\appdata\local\programs\python\python38\Lib\smtplib.py", line 339, in connect
    self.sock = self._get_socket(host, port, self.timeout)
  File "c:\users\admin\appdata\local\programs\python\python38\Lib\smtplib.py", line 308, in _get_socket
    return socket.create_connection((host, port), timeout,
  File "c:\users\admin\appdata\local\programs\python\python38\Lib\socket.py", line 807, in create_connection
    raise err
  File "c:\users\admin\appdata\local\programs\python\python38\Lib\socket.py", line 796, in create_connection
    sock.connect(sa)
ConnectionRefusedError: [WinError 10061] No connection could be made because the target machine actively refused it
2020-02-08 18:13:56,533 INFO: Microblog startup [in C:\Users\Admin\Desktop\flask-demo-app\app\__init__.py:55]
2020-02-08 18:14:14,455 INFO: Microblog startup [in C:\Users\Admin\Desktop\flask-demo-app\app\__init__.py:55]
2020-02-08 18:14:54,775 INFO: Microblog startup [in C:\Users\Admin\Desktop\flask-demo-app\app\__init__.py:55]
2020-02-08 18:18:37,484 ERROR: Exception on /reset_password_request [POST] [in c:\users\admin\desktop\flask-demo-app\venv\lib\site-packages\flask\app.py:1890]
Traceback (most recent call last):
  File "c:\users\admin\desktop\flask-demo-app\venv\lib\site-packages\flask\app.py", line 2446, in wsgi_app
    response = self.full_dispatch_request()
  File "c:\users\admin\desktop\flask-demo-app\venv\lib\site-packages\flask\app.py", line 1951, in full_dispatch_request
    rv = self.handle_user_exception(e)
  File "c:\users\admin\desktop\flask-demo-app\venv\lib\site-packages\flask\app.py", line 1820, in handle_user_exception
    reraise(exc_type, exc_value, tb)
  File "c:\users\admin\desktop\flask-demo-app\venv\lib\site-packages\flask\_compat.py", line 39, in reraise
    raise value
  File "c:\users\admin\desktop\flask-demo-app\venv\lib\site-packages\flask\app.py", line 1949, in full_dispatch_request
    rv = self.dispatch_request()
  File "c:\users\admin\desktop\flask-demo-app\venv\lib\site-packages\flask\app.py", line 1935, in dispatch_request
    return self.view_functions[rule.endpoint](**req.view_args)
  File "C:\Users\Admin\Desktop\flask-demo-app\app\routes.py", line 154, in reset_password_request
    send_password_reset_email(user)
  File "C:\Users\Admin\Desktop\flask-demo-app\app\email.py", line 13, in send_password_reset_email
    send_email(
  File "C:\Users\Admin\Desktop\flask-demo-app\app\email.py", line 9, in send_email
    mail.send(msg)
  File "c:\users\admin\desktop\flask-demo-app\venv\lib\site-packages\flask_mail.py", line 491, in send
    with self.connect() as connection:
  File "c:\users\admin\desktop\flask-demo-app\venv\lib\site-packages\flask_mail.py", line 144, in __enter__
    self.host = self.configure_host()
  File "c:\users\admin\desktop\flask-demo-app\venv\lib\site-packages\flask_mail.py", line 158, in configure_host
    host = smtplib.SMTP(self.mail.server, self.mail.port)
  File "c:\users\admin\appdata\local\programs\python\python38\Lib\smtplib.py", line 253, in __init__
    (code, msg) = self.connect(host, port)
  File "c:\users\admin\appdata\local\programs\python\python38\Lib\smtplib.py", line 339, in connect
    self.sock = self._get_socket(host, port, self.timeout)
  File "c:\users\admin\appdata\local\programs\python\python38\Lib\smtplib.py", line 308, in _get_socket
    return socket.create_connection((host, port), timeout,
  File "c:\users\admin\appdata\local\programs\python\python38\Lib\socket.py", line 807, in create_connection
    raise err
  File "c:\users\admin\appdata\local\programs\python\python38\Lib\socket.py", line 796, in create_connection
    sock.connect(sa)
ConnectionRefusedError: [WinError 10061] No connection could be made because the target machine actively refused it
